<mujoco model="empty_floor">
  <compiler angle="radian"/>

  <option timestep="0.001" integrator="implicitfast">
    <flag energy="enable"/>
  </option>

  <visual>
    <global azimuth="120" elevation="-20"/>
    <rgba haze="0.15 0.25 0.35 1"/>
  </visual>

  <default>
    <default class="panda">
      <material shininess="0.25"/>
      <joint range="-2.8973 2.8973" armature="0.1" damping="1"/>
      <site size="0.001 0.005 0.005" group="4" rgba="0.5 0.5 0.5 0.3"/>
      <general ctrlrange="-2.8973 2.8973" forcerange="-87 87" biastype="affine"/>
      <default class="panda/visual">
        <geom type="mesh" contype="0" conaffinity="0" group="2"/>
      </default>
      <default class="panda/collision">
        <geom type="mesh" group="3"/>
      </default>
    </default>
    <default class="panda_hand">
      <material shininess="0.25"/>
      <joint range="-2.8973 2.8973" armature="0.1" damping="1"/>
      <general ctrlrange="-2.8973 2.8973" forcerange="-87 87" biastype="affine"/>
      <default class="finger">
        <joint type="slide" range="0 0.04"/>
      </default>
      <default class="visual">
        <geom type="mesh" contype="0" conaffinity="0" group="2"/>
      </default>
      <default class="collision">
        <geom type="mesh" contype="0" condim="4" group="4" friction="1 1 1" solimp="1 1 1"/>
        <default class="fingertip_pad_collision_1">
          <geom size="0.0085 0.004 0.0085" type="box"/>
        </default>
        <default class="fingertip_pad_collision_2">
          <geom size="0.003 0.002 0.003" type="box"/>
        </default>
        <default class="fingertip_pad_collision_3">
          <geom size="0.003 0.002 0.003" type="box"/>
        </default>
        <default class="fingertip_pad_collision_4">
          <geom size="0.003 0.002 0.0035" type="box"/>
        </default>
        <default class="fingertip_pad_collision_5">
          <geom size="0.003 0.002 0.0035" type="box"/>
        </default>
      </default>
    </default>
  </default>

  <asset>
    <texture type="skybox" builtin="gradient" rgb1="0.3 0.5 0.7" rgb2="0 0 0" width="512" height="3072"/>
    <texture type="2d" name="groundplane" builtin="checker" mark="edge" rgb1="0.2 0.3 0.4" rgb2="0.1 0.2 0.3" markrgb="0.8 0.8 0.8" width="300" height="300"/>
    <texture type="2d" name="tex-basket" file="texture.png"/>
    <material name="groundplane" texture="groundplane" texuniform="true" texrepeat="5 5" reflectance="0.2"/>
    <material name="white" class="panda"/>
    <material name="off_white" class="panda" rgba="0.901961 0.921569 0.929412 1"/>
    <material name="dark_grey" class="panda" rgba="0.25 0.25 0.25 1"/>
    <material name="green" class="panda" rgba="0 1 0 1"/>
    <material name="light_blue" class="panda" rgba="0.039216 0.541176 0.780392 1"/>
    <material name="white_hand" class="panda_hand"/>
    <material name="off_white_hand" class="panda_hand" rgba="0.901961 0.921569 0.929412 1"/>
    <material name="black_hand" class="panda_hand" rgba="0.25 0.25 0.25 1"/>
    <material name="basket" texture="tex-basket" reflectance="0.5"/>
    <mesh name="0_link0_c" file="G:\LJN/Master/Projects/XRobotProject/Project/Code/RobotTask/XRobot/assets/models/manipulators/Panda/meshes/link0.stl"/>
    <mesh name="0_link1_c" file="G:\LJN/Master/Projects/XRobotProject/Project/Code/RobotTask/XRobot/assets/models/manipulators/Panda/meshes/link1.stl"/>
    <mesh name="0_link2_c" file="G:\LJN/Master/Projects/XRobotProject/Project/Code/RobotTask/XRobot/assets/models/manipulators/Panda/meshes/link2.stl"/>
    <mesh name="0_link3_c" file="G:\LJN/Master/Projects/XRobotProject/Project/Code/RobotTask/XRobot/assets/models/manipulators/Panda/meshes/link3.stl"/>
    <mesh name="0_link4_c" file="G:\LJN/Master/Projects/XRobotProject/Project/Code/RobotTask/XRobot/assets/models/manipulators/Panda/meshes/link4.stl"/>
    <mesh name="0_link5_c0" file="G:\LJN/Master/Projects/XRobotProject/Project/Code/RobotTask/XRobot/assets/models/manipulators/Panda/meshes/link5_collision_0.obj"/>
    <mesh name="0_link5_c1" file="G:\LJN/Master/Projects/XRobotProject/Project/Code/RobotTask/XRobot/assets/models/manipulators/Panda/meshes/link5_collision_1.obj"/>
    <mesh name="0_link5_c2" file="G:\LJN/Master/Projects/XRobotProject/Project/Code/RobotTask/XRobot/assets/models/manipulators/Panda/meshes/link5_collision_2.obj"/>
    <mesh name="0_link6_c" file="G:\LJN/Master/Projects/XRobotProject/Project/Code/RobotTask/XRobot/assets/models/manipulators/Panda/meshes/link6.stl"/>
    <mesh name="0_link7_c" file="G:\LJN/Master/Projects/XRobotProject/Project/Code/RobotTask/XRobot/assets/models/manipulators/Panda/meshes/link7.stl"/>
    <mesh name="link0_0" file="G:\LJN/Master/Projects/XRobotProject/Project/Code/RobotTask/XRobot/assets/models/manipulators/Panda/meshes/link0_0.obj"/>
    <mesh name="link0_1" file="G:\LJN/Master/Projects/XRobotProject/Project/Code/RobotTask/XRobot/assets/models/manipulators/Panda/meshes/link0_1.obj"/>
    <mesh name="link0_2" file="G:\LJN/Master/Projects/XRobotProject/Project/Code/RobotTask/XRobot/assets/models/manipulators/Panda/meshes/link0_2.obj"/>
    <mesh name="link0_3" file="G:\LJN/Master/Projects/XRobotProject/Project/Code/RobotTask/XRobot/assets/models/manipulators/Panda/meshes/link0_3.obj"/>
    <mesh name="link0_4" file="G:\LJN/Master/Projects/XRobotProject/Project/Code/RobotTask/XRobot/assets/models/manipulators/Panda/meshes/link0_4.obj"/>
    <mesh name="link0_5" file="G:\LJN/Master/Projects/XRobotProject/Project/Code/RobotTask/XRobot/assets/models/manipulators/Panda/meshes/link0_5.obj"/>
    <mesh name="link0_7" file="G:\LJN/Master/Projects/XRobotProject/Project/Code/RobotTask/XRobot/assets/models/manipulators/Panda/meshes/link0_7.obj"/>
    <mesh name="link0_8" file="G:\LJN/Master/Projects/XRobotProject/Project/Code/RobotTask/XRobot/assets/models/manipulators/Panda/meshes/link0_8.obj"/>
    <mesh name="link0_9" file="G:\LJN/Master/Projects/XRobotProject/Project/Code/RobotTask/XRobot/assets/models/manipulators/Panda/meshes/link0_9.obj"/>
    <mesh name="link0_10" file="G:\LJN/Master/Projects/XRobotProject/Project/Code/RobotTask/XRobot/assets/models/manipulators/Panda/meshes/link0_10.obj"/>
    <mesh name="link0_11" file="G:\LJN/Master/Projects/XRobotProject/Project/Code/RobotTask/XRobot/assets/models/manipulators/Panda/meshes/link0_11.obj"/>
    <mesh name="link1" file="G:\LJN/Master/Projects/XRobotProject/Project/Code/RobotTask/XRobot/assets/models/manipulators/Panda/meshes/link1.obj"/>
    <mesh name="link2" file="G:\LJN/Master/Projects/XRobotProject/Project/Code/RobotTask/XRobot/assets/models/manipulators/Panda/meshes/link2.obj"/>
    <mesh name="link3_0" file="G:\LJN/Master/Projects/XRobotProject/Project/Code/RobotTask/XRobot/assets/models/manipulators/Panda/meshes/link3_0.obj"/>
    <mesh name="link3_1" file="G:\LJN/Master/Projects/XRobotProject/Project/Code/RobotTask/XRobot/assets/models/manipulators/Panda/meshes/link3_1.obj"/>
    <mesh name="link3_2" file="G:\LJN/Master/Projects/XRobotProject/Project/Code/RobotTask/XRobot/assets/models/manipulators/Panda/meshes/link3_2.obj"/>
    <mesh name="link3_3" file="G:\LJN/Master/Projects/XRobotProject/Project/Code/RobotTask/XRobot/assets/models/manipulators/Panda/meshes/link3_3.obj"/>
    <mesh name="link4_0" file="G:\LJN/Master/Projects/XRobotProject/Project/Code/RobotTask/XRobot/assets/models/manipulators/Panda/meshes/link4_0.obj"/>
    <mesh name="link4_1" file="G:\LJN/Master/Projects/XRobotProject/Project/Code/RobotTask/XRobot/assets/models/manipulators/Panda/meshes/link4_1.obj"/>
    <mesh name="link4_2" file="G:\LJN/Master/Projects/XRobotProject/Project/Code/RobotTask/XRobot/assets/models/manipulators/Panda/meshes/link4_2.obj"/>
    <mesh name="link4_3" file="G:\LJN/Master/Projects/XRobotProject/Project/Code/RobotTask/XRobot/assets/models/manipulators/Panda/meshes/link4_3.obj"/>
    <mesh name="link5_0" file="G:\LJN/Master/Projects/XRobotProject/Project/Code/RobotTask/XRobot/assets/models/manipulators/Panda/meshes/link5_0.obj"/>
    <mesh name="link5_1" file="G:\LJN/Master/Projects/XRobotProject/Project/Code/RobotTask/XRobot/assets/models/manipulators/Panda/meshes/link5_1.obj"/>
    <mesh name="link5_2" file="G:\LJN/Master/Projects/XRobotProject/Project/Code/RobotTask/XRobot/assets/models/manipulators/Panda/meshes/link5_2.obj"/>
    <mesh name="link6_0" file="G:\LJN/Master/Projects/XRobotProject/Project/Code/RobotTask/XRobot/assets/models/manipulators/Panda/meshes/link6_0.obj"/>
    <mesh name="link6_1" file="G:\LJN/Master/Projects/XRobotProject/Project/Code/RobotTask/XRobot/assets/models/manipulators/Panda/meshes/link6_1.obj"/>
    <mesh name="link6_2" file="G:\LJN/Master/Projects/XRobotProject/Project/Code/RobotTask/XRobot/assets/models/manipulators/Panda/meshes/link6_2.obj"/>
    <mesh name="link6_3" file="G:\LJN/Master/Projects/XRobotProject/Project/Code/RobotTask/XRobot/assets/models/manipulators/Panda/meshes/link6_3.obj"/>
    <mesh name="link6_4" file="G:\LJN/Master/Projects/XRobotProject/Project/Code/RobotTask/XRobot/assets/models/manipulators/Panda/meshes/link6_4.obj"/>
    <mesh name="link6_5" file="G:\LJN/Master/Projects/XRobotProject/Project/Code/RobotTask/XRobot/assets/models/manipulators/Panda/meshes/link6_5.obj"/>
    <mesh name="link6_6" file="G:\LJN/Master/Projects/XRobotProject/Project/Code/RobotTask/XRobot/assets/models/manipulators/Panda/meshes/link6_6.obj"/>
    <mesh name="link6_7" file="G:\LJN/Master/Projects/XRobotProject/Project/Code/RobotTask/XRobot/assets/models/manipulators/Panda/meshes/link6_7.obj"/>
    <mesh name="link6_8" file="G:\LJN/Master/Projects/XRobotProject/Project/Code/RobotTask/XRobot/assets/models/manipulators/Panda/meshes/link6_8.obj"/>
    <mesh name="link6_9" file="G:\LJN/Master/Projects/XRobotProject/Project/Code/RobotTask/XRobot/assets/models/manipulators/Panda/meshes/link6_9.obj"/>
    <mesh name="link6_10" file="G:\LJN/Master/Projects/XRobotProject/Project/Code/RobotTask/XRobot/assets/models/manipulators/Panda/meshes/link6_10.obj"/>
    <mesh name="link6_11" file="G:\LJN/Master/Projects/XRobotProject/Project/Code/RobotTask/XRobot/assets/models/manipulators/Panda/meshes/link6_11.obj"/>
    <mesh name="link6_12" file="G:\LJN/Master/Projects/XRobotProject/Project/Code/RobotTask/XRobot/assets/models/manipulators/Panda/meshes/link6_12.obj"/>
    <mesh name="link6_13" file="G:\LJN/Master/Projects/XRobotProject/Project/Code/RobotTask/XRobot/assets/models/manipulators/Panda/meshes/link6_13.obj"/>
    <mesh name="link6_14" file="G:\LJN/Master/Projects/XRobotProject/Project/Code/RobotTask/XRobot/assets/models/manipulators/Panda/meshes/link6_14.obj"/>
    <mesh name="link6_15" file="G:\LJN/Master/Projects/XRobotProject/Project/Code/RobotTask/XRobot/assets/models/manipulators/Panda/meshes/link6_15.obj"/>
    <mesh name="link6_16" file="G:\LJN/Master/Projects/XRobotProject/Project/Code/RobotTask/XRobot/assets/models/manipulators/Panda/meshes/link6_16.obj"/>
    <mesh name="link7_0" file="G:\LJN/Master/Projects/XRobotProject/Project/Code/RobotTask/XRobot/assets/models/manipulators/Panda/meshes/link7_0.obj"/>
    <mesh name="link7_1" file="G:\LJN/Master/Projects/XRobotProject/Project/Code/RobotTask/XRobot/assets/models/manipulators/Panda/meshes/link7_1.obj"/>
    <mesh name="link7_2" file="G:\LJN/Master/Projects/XRobotProject/Project/Code/RobotTask/XRobot/assets/models/manipulators/Panda/meshes/link7_2.obj"/>
    <mesh name="link7_3" file="G:\LJN/Master/Projects/XRobotProject/Project/Code/RobotTask/XRobot/assets/models/manipulators/Panda/meshes/link7_3.obj"/>
    <mesh name="link7_4" file="G:\LJN/Master/Projects/XRobotProject/Project/Code/RobotTask/XRobot/assets/models/manipulators/Panda/meshes/link7_4.obj"/>
    <mesh name="link7_5" file="G:\LJN/Master/Projects/XRobotProject/Project/Code/RobotTask/XRobot/assets/models/manipulators/Panda/meshes/link7_5.obj"/>
    <mesh name="link7_6" file="G:\LJN/Master/Projects/XRobotProject/Project/Code/RobotTask/XRobot/assets/models/manipulators/Panda/meshes/link7_6.obj"/>
    <mesh name="link7_7" file="G:\LJN/Master/Projects/XRobotProject/Project/Code/RobotTask/XRobot/assets/models/manipulators/Panda/meshes/link7_7.obj"/>
    <mesh name="0_hand_c" file="G:\LJN/Master/Projects/XRobotProject/Project/Code/RobotTask/XRobot/assets/models/grippers/PandaHand/meshes/hand.stl"/>
    <mesh name="hand_0" file="G:\LJN/Master/Projects/XRobotProject/Project/Code/RobotTask/XRobot/assets/models/grippers/PandaHand/meshes/hand_0.obj"/>
    <mesh name="hand_1" file="G:\LJN/Master/Projects/XRobotProject/Project/Code/RobotTask/XRobot/assets/models/grippers/PandaHand/meshes/hand_1.obj"/>
    <mesh name="hand_2" file="G:\LJN/Master/Projects/XRobotProject/Project/Code/RobotTask/XRobot/assets/models/grippers/PandaHand/meshes/hand_2.obj"/>
    <mesh name="hand_3" file="G:\LJN/Master/Projects/XRobotProject/Project/Code/RobotTask/XRobot/assets/models/grippers/PandaHand/meshes/hand_3.obj"/>
    <mesh name="hand_4" file="G:\LJN/Master/Projects/XRobotProject/Project/Code/RobotTask/XRobot/assets/models/grippers/PandaHand/meshes/hand_4.obj"/>
    <mesh name="finger_0" file="G:\LJN/Master/Projects/XRobotProject/Project/Code/RobotTask/XRobot/assets/models/grippers/PandaHand/meshes/finger_0.obj"/>
    <mesh name="finger_1" file="G:\LJN/Master/Projects/XRobotProject/Project/Code/RobotTask/XRobot/assets/models/grippers/PandaHand/meshes/finger_1.obj"/>
    <mesh name="basket_vis" file="basket_vis.msh"/>
  </asset>

  <worldbody>
    <geom name="floor" size="3 3 0.125" type="plane" rgba="1 1 1 1"/>
    <camera name="frontview" pos="1.5 0 0.5" quat="0.560842 0.430646 0.430646 0.560842"/>
    <camera name="birdview" pos="-0.2 0 3" quat="0.707107 0 0 0.707107"/>
    <camera name="0_cam" pos="0.5 0 1" quat="0.707107 0 0 -0.707107"/>
    <light pos="1 1 8" dir="0 -0.14834 -0.988936" castshadow="false" diffuse="0.8 0.8 0.8"/>
    <light pos="-3 -3 8" dir="0 -0.14834 -0.988936" castshadow="false" diffuse="0.8 0.8 0.8"/>
    <body name="0_link0" childclass="panda">
      <inertial pos="-0.041018 -0.00014 0.049974" quat="0.00630474 0.751245 0.00741774 0.659952" mass="0.629769" diaginertia="0.00430465 0.00387984 0.00313051"/>
      <geom class="panda/visual" material="off_white" mesh="link0_0"/>
      <geom class="panda/visual" material="dark_grey" mesh="link0_1"/>
      <geom class="panda/visual" material="off_white" mesh="link0_2"/>
      <geom class="panda/visual" material="dark_grey" mesh="link0_3"/>
      <geom class="panda/visual" material="off_white" mesh="link0_4"/>
      <geom class="panda/visual" material="dark_grey" mesh="link0_5"/>
      <geom class="panda/visual" material="white" mesh="link0_7"/>
      <geom class="panda/visual" material="white" mesh="link0_8"/>
      <geom class="panda/visual" material="dark_grey" mesh="link0_9"/>
      <geom class="panda/visual" material="off_white" mesh="link0_10"/>
      <geom class="panda/visual" material="white" mesh="link0_11"/>
      <geom class="panda/collision" mesh="0_link0_c"/>
      <site name="0_b_x" pos="0.1 0 0" quat="0.707105 0 0.707108 0" size="0.005 0.1" group="1" type="cylinder" rgba="1 0 0 0.1"/>
      <site name="0_b_y" pos="0 0.1 0" quat="0.707105 0.707108 0 0" size="0.005 0.1" group="1" type="cylinder" rgba="0 1 0 0.1"/>
      <site name="0_b_z" pos="0 0 0.1" size="0.005 0.1" group="1" type="cylinder" rgba="0 0 1 0.1"/>
      <body name="0_link1" pos="0 0 0.333">
        <inertial pos="0.003875 0.002081 -0.04762" quat="0.711549 0.00634377 -0.0131124 0.702485" mass="4.97068" diaginertia="0.707137 0.703435 0.00852456"/>
        <joint name="0_joint1" pos="0 0 0" axis="0 0 1" limited="true" damping="0.1"/>
        <geom class="panda/visual" material="white" mesh="link1"/>
        <geom class="panda/collision" mesh="0_link1_c"/>
        <body name="0_link2" quat="0.707107 -0.707107 0 0">
          <inertial pos="-0.003141 -0.02872 0.003495" quat="-0.168175 0.828366 -0.122878 0.520027" mass="0.646926" diaginertia="0.0310326 0.0283001 0.00273425"/>
          <joint name="0_joint2" pos="0 0 0" axis="0 0 1" limited="true" range="-1.7628 1.7628" damping="0.1"/>
          <geom class="panda/visual" material="white" mesh="link2"/>
          <geom class="panda/collision" mesh="0_link2_c"/>
          <body name="0_link3" pos="0 -0.316 0" quat="0.707107 0.707107 0 0">
            <inertial pos="0.027518 0.039252 -0.066502" quat="0.662769 -0.00678331 0.252053 0.705096" mass="3.2286" diaginertia="0.0415014 0.0414793 0.00124635"/>
            <joint name="0_joint3" pos="0 0 0" axis="0 0 1" limited="true" damping="0.1"/>
            <geom class="panda/visual" material="white" mesh="link3_0"/>
            <geom class="panda/visual" material="white" mesh="link3_1"/>
            <geom class="panda/visual" material="white" mesh="link3_2"/>
            <geom class="panda/visual" material="dark_grey" mesh="link3_3"/>
            <geom class="panda/collision" mesh="0_link3_c"/>
            <body name="0_link4" pos="0.0825 0 0" quat="0.707107 0.707107 0 0">
              <inertial pos="-0.05317 0.104419 0.027454" quat="0.65058 0.529822 -0.0962034 0.535518" mass="3.5879" diaginertia="0.0349596 0.0281483 0.0106201"/>
              <joint name="0_joint4" pos="0 0 0" axis="0 0 1" limited="true" range="-3.0718 -0.0698" damping="0.1"/>
              <geom class="panda/visual" material="white" mesh="link4_0"/>
              <geom class="panda/visual" material="white" mesh="link4_1"/>
              <geom class="panda/visual" material="dark_grey" mesh="link4_2"/>
              <geom class="panda/visual" material="white" mesh="link4_3"/>
              <geom class="panda/collision" mesh="0_link4_c"/>
              <body name="0_link5" pos="-0.0825 0.384 0" quat="0.707107 -0.707107 0 0">
                <inertial pos="-0.011953 0.041065 -0.038437" quat="0.987313 -0.0121954 0.0719187 -0.141037" mass="1.22595" diaginertia="0.0367625 0.0288531 0.00803437"/>
                <joint name="0_joint5" pos="0 0 0" axis="0 0 1" limited="true" damping="0.1"/>
                <geom class="panda/visual" material="dark_grey" mesh="link5_0"/>
                <geom class="panda/visual" material="white" mesh="link5_1"/>
                <geom class="panda/visual" material="white" mesh="link5_2"/>
                <geom class="panda/collision" mesh="0_link5_c0"/>
                <geom class="panda/collision" mesh="0_link5_c1"/>
                <geom class="panda/collision" mesh="0_link5_c2"/>
                <body name="0_link6" quat="0.707107 0.707107 0 0">
                  <inertial pos="0.060149 -0.014117 -0.010517" quat="0.101075 0.59332 0.0287227 0.798079" mass="1.66656" diaginertia="0.00584276 0.00431037 0.00159787"/>
                  <joint name="0_joint6" pos="0 0 0" axis="0 0 1" limited="true" range="-0.0175 3.7525" damping="0.01"/>
                  <geom class="panda/visual" material="off_white" mesh="link6_0"/>
                  <geom class="panda/visual" material="white" mesh="link6_1"/>
                  <geom class="panda/visual" material="dark_grey" mesh="link6_2"/>
                  <geom class="panda/visual" material="white" mesh="link6_3"/>
                  <geom class="panda/visual" material="white" mesh="link6_4"/>
                  <geom class="panda/visual" material="white" mesh="link6_5"/>
                  <geom class="panda/visual" material="white" mesh="link6_6"/>
                  <geom class="panda/visual" material="light_blue" mesh="link6_7"/>
                  <geom class="panda/visual" material="light_blue" mesh="link6_8"/>
                  <geom class="panda/visual" material="dark_grey" mesh="link6_9"/>
                  <geom class="panda/visual" material="dark_grey" mesh="link6_10"/>
                  <geom class="panda/visual" material="white" mesh="link6_11"/>
                  <geom class="panda/visual" material="green" mesh="link6_12"/>
                  <geom class="panda/visual" material="white" mesh="link6_13"/>
                  <geom class="panda/visual" material="dark_grey" mesh="link6_14"/>
                  <geom class="panda/visual" material="dark_grey" mesh="link6_15"/>
                  <geom class="panda/visual" material="white" mesh="link6_16"/>
                  <geom class="panda/collision" mesh="0_link6_c"/>
                  <body name="0_link7" pos="0.088 0 0" quat="0.707107 0.707107 0 0">
                    <inertial pos="0.010517 -0.004252 0.061597" quat="0.992939 -0.0762041 0.0733595 -0.0537067" mass="0.735522" diaginertia="0.0127345 0.0101055 0.00451803"/>
                    <joint name="0_joint7" pos="0 0 0" axis="0 0 1" limited="true" damping="0.01"/>
                    <geom class="panda/visual" material="white" mesh="link7_0"/>
                    <geom class="panda/visual" material="dark_grey" mesh="link7_1"/>
                    <geom class="panda/visual" material="dark_grey" mesh="link7_2"/>
                    <geom class="panda/visual" material="dark_grey" mesh="link7_3"/>
                    <geom class="panda/visual" material="dark_grey" mesh="link7_4"/>
                    <geom class="panda/visual" material="dark_grey" mesh="link7_5"/>
                    <geom class="panda/visual" material="dark_grey" mesh="link7_6"/>
                    <geom class="panda/visual" material="white" mesh="link7_7"/>
                    <geom class="panda/collision" mesh="0_link7_c"/>
                    <body name="0_attachment" pos="0 0 0.107" quat="0.382683 0 0 0.92388">
                      <site name="0_attachment_site" pos="0 0 0"/>
                      <body name="0_hand" childclass="panda_hand" quat="0 0 0 1">
                        <inertial pos="-0.01 0 0.03" mass="0.73" diaginertia="0.001 0.0025 0.0017"/>
                        <geom class="visual" material="off_white_hand" mesh="hand_0"/>
                        <geom class="visual" material="black_hand" mesh="hand_1"/>
                        <geom class="visual" material="black_hand" mesh="hand_2"/>
                        <geom class="visual" material="white_hand" mesh="hand_3"/>
                        <geom class="visual" material="off_white_hand" mesh="hand_4"/>
                        <geom class="collision" mesh="0_hand_c"/>
                        <body name="0_eef" pos="0 0 0.1" quat="0 1 0 0"/>
                        <body name="0_left_finger" pos="0 0 0.0584">
                          <inertial pos="0 0 0" mass="0.015" diaginertia="2.375e-06 2.375e-06 7.5e-07"/>
                          <joint name="0_finger_joint1" class="finger" pos="0 0 0" axis="0 1 0"/>
                          <geom class="visual" material="off_white_hand" mesh="finger_0"/>
                          <geom class="visual" material="black_hand" mesh="finger_1"/>
                          <geom class="collision" mesh="finger_0"/>
                          <geom class="fingertip_pad_collision_1" pos="0 0.0055 0.0445"/>
                          <geom class="fingertip_pad_collision_2" pos="0.0055 0.002 0.05"/>
                          <geom class="fingertip_pad_collision_3" pos="-0.0055 0.002 0.05"/>
                          <geom class="fingertip_pad_collision_4" pos="0.0055 0.002 0.0395"/>
                          <geom class="fingertip_pad_collision_5" pos="-0.0055 0.002 0.0395"/>
                        </body>
                        <body name="0_right_finger" pos="0 0 0.0584" quat="0 0 0 1">
                          <inertial pos="0 0 0" mass="0.015" diaginertia="2.375e-06 2.375e-06 7.5e-07"/>
                          <joint name="0_finger_joint2" class="finger" pos="0 0 0" axis="0 1 0"/>
                          <geom class="visual" material="off_white_hand" mesh="finger_0"/>
                          <geom class="visual" material="black_hand" mesh="finger_1"/>
                          <geom class="collision" mesh="finger_0"/>
                          <geom class="fingertip_pad_collision_1" pos="0 0.0055 0.0445"/>
                          <geom class="fingertip_pad_collision_2" pos="0.0055 0.002 0.05"/>
                          <geom class="fingertip_pad_collision_3" pos="-0.0055 0.002 0.05"/>
                          <geom class="fingertip_pad_collision_4" pos="0.0055 0.002 0.0395"/>
                          <geom class="fingertip_pad_collision_5" pos="-0.0055 0.002 0.0395"/>
                        </body>
                      </body>
                    </body>
                  </body>
                </body>
              </body>
            </body>
          </body>
        </body>
      </body>
    </body>
    <body name="red_block" pos="0.4 0.3 0.1" quat="0.926359 0 0 -0.376641">
      <joint type="free" limited="false" actuatorfrclimited="false"/>
      <geom size="0.02 0.02 0.02" type="box" contype="0" conaffinity="0" group="1" rgba="1 0 0 1"/>
      <geom size="0.02 0.02 0.02" type="box" condim="4" group="4" solref="1e-05" solimp="1 1 1" mass="0.0001"/>
      <site name="red_block" pos="0 0 0" size="0.02" rgba="1 0 0 0.5"/>
    </body>
    <body name="green_block" pos="0.6 0.2 0.1" quat="0.965886 0 0 0.258969">
      <joint type="free" limited="false" actuatorfrclimited="false"/>
      <geom size="0.02 0.02 0.02" type="box" contype="0" conaffinity="0" group="1" rgba="0 1 0 1"/>
      <geom size="0.02 0.02 0.02" type="box" condim="4" group="4" solref="1e-05" solimp="1 1 1" mass="0.0001"/>
      <site name="green_block" pos="0 0 0" size="0.02" rgba="0 1 0 0.5"/>
    </body>
    <body name="blue_block" pos="0.5 0.3 0.1" quat="0.866019 0 0 0.500011">
      <joint type="free" limited="false" actuatorfrclimited="false"/>
      <geom size="0.02 0.02 0.02" type="box" contype="0" conaffinity="0" group="1" rgba="0 0 1 1"/>
      <geom size="0.02 0.02 0.02" type="box" condim="4" group="4" solref="1e-05" solimp="1 1 1" mass="0.0001"/>
      <site name="blue_block" pos="0 0 0" size="0.02" rgba="0 0 1 0.5"/>
    </body>
    <body name="orange_block" pos="0.5 0.2 0.1" quat="0.984753 0 0 0.173956">
      <joint type="free" limited="false" actuatorfrclimited="false"/>
      <geom size="0.02 0.02 0.02" type="box" contype="0" conaffinity="0" group="1" rgba="1 0.5 0 1"/>
      <geom size="0.02 0.02 0.02" type="box" condim="4" group="4" solref="1e-05" solimp="1 1 1" mass="0.0001"/>
      <site name="orange_block" pos="0 0 0" size="0.02" rgba="1 0.5 0 0.5"/>
    </body>
    <body name="square_nut" pos="0.6 0.1 0.1" quat="0.382911 0 0 -0.923785">
      <joint type="free" limited="false" actuatorfrclimited="false"/>
      <geom size="0.0105 0.04375 0.01" pos="-0.03325 0 0" type="box" condim="4" friction="0.95 0.3 0.2" solimp="0.998 0.998" density="100" rgba="0.17 0.22 0.23 1"/>
      <geom size="0.03125 0.0105 0.01" pos="0 0.03325 0" type="box" condim="4" friction="0.95 0.3 0.1" solimp="0.998 0.998" density="100" rgba="0.17 0.22 0.23 1"/>
      <geom size="0.03125 0.0105 0.01" pos="0 -0.03325 0" type="box" condim="4" friction="0.95 0.3 0.1" solimp="0.998 0.998" density="100" rgba="0.17 0.22 0.23 1"/>
      <geom size="0.0105 0.04375 0.01" pos="0.03325 0 0" type="box" condim="4" friction="0.95 0.3 0.1" solimp="0.998 0.998" density="100" rgba="0.17 0.22 0.23 1"/>
      <geom size="0.02525 0.015875 0.01" pos="0.054 0 0" type="box" condim="4" friction="0.95 0.3 0.1" solimp="0.998 0.998" density="100" rgba="0.17 0.22 0.23 1"/>
    </body>
    <body name="basket" pos="0.7 -0.2 0">
      <geom type="mesh" contype="0" conaffinity="0" group="1" friction="0.95 0.3 0.1" solref="0.001" solimp="0.998 0.998" density="100" material="basket" mesh="basket_vis"/>
      <geom size="0.0085 0.0724 0.07658" pos="0.00251 0 0.01308" quat="0.7088 0 0.70541 0" type="box" friction="0.95 0.3 0.1" solref="0.001" solimp="0.998 0.998" density="100" rgba="0.8 0.8 0.8 0.3"/>
      <geom size="0.00667 0.06368 0.0724" pos="-0.07265 0 0.07657" quat="0.0267201 -0.0267201 0.706602 0.706602" type="box" friction="0.95 0.3 0.1" solref="0.001" solimp="0.998 0.998" density="100" rgba="0.8 0.8 0.8 0.3"/>
      <geom size="0.00667 0.06368 0.0724" pos="0.00047 -0.06855 0.08177" quat="0.512632 -0.490251 0.509562 -0.487041" type="box" friction="0.95 0.3 0.1" solref="0.001" solimp="0.998 0.998" density="100" rgba="0.8 0.8 0.8 0.3"/>
      <geom size="0.00667 0.06368 0.0724" pos="-0.0002 0.06909 0.08177" quat="0.487941 -0.510431 -0.489351 0.511771" type="box" friction="0.95 0.3 0.1" solref="0.001" solimp="0.998 0.998" density="100" rgba="0.8 0.8 0.8 0.3"/>
      <geom size="0.00667 0.06368 0.0724" pos="0.07557 0 0.07657" quat="0.0176499 0.0176499 -0.706886 0.706886" type="box" friction="0.95 0.3 0.1" solref="0.001" solimp="0.998 0.998" density="100" rgba="0.8 0.8 0.8 0.3"/>
      <site name="contain_region" pos="0 0 0.07185" quat="0 0 0 1" size="0.06108 0.06108 0.06949" type="box" rgba="0.8 0 0 0"/>
    </body>
    <body name="red_box" pos="0.4 -0.4 0">
      <geom size="0.05 0.005" type="cylinder" contype="0" conaffinity="0" group="1" rgba="1 0 0 1"/>
      <site pos="0 0 0.02" size="0.02 0.02 0.02" type="box" rgba="1 0 0 0.2"/>
    </body>
    <body name="green_box" pos="0.4 -0.3 0">
      <geom size="0.05 0.005" type="cylinder" contype="0" conaffinity="0" group="1" rgba="0 1 0 0.5"/>
      <site pos="0 0 0.02" size="0.02 0.02 0.02" type="box" rgba="0 1 0 0.2"/>
    </body>
    <body name="blue_box" pos="0.5 -0.4 0">
      <geom size="0.05 0.005" type="cylinder" contype="0" conaffinity="0" group="1" rgba="0 0 1 1"/>
      <site pos="0 0 0.02" size="0.02 0.02 0.02" type="box" rgba="0 0 1 0.2"/>
    </body>
    <body name="orange_box" pos="0.5 -0.3 0">
      <geom size="0.05 0.005" type="cylinder" contype="0" conaffinity="0" group="1" rgba="1 0.5 0 1"/>
      <site pos="0 0 0.02" size="0.02 0.02 0.02" type="box" rgba="1 0.5 0 0.2"/>
    </body>
  </worldbody>

  <contact>
    <exclude body1="0_hand" body2="0_left_finger"/>
    <exclude body1="0_hand" body2="0_right_finger"/>
  </contact>

  <equality>
    <joint joint1="0_finger_joint1" joint2="0_finger_joint2" polycoef="0 1 0 0 0" solref="0.005" solimp="0.95 0.99"/>
  </equality>

  <tendon>
    <fixed name="0_split">
      <joint joint="0_finger_joint1" coef="0.5"/>
      <joint joint="0_finger_joint2" coef="0.5"/>
    </fixed>
  </tendon>

  <actuator>
    <general name="0_actuator1" joint="0_joint1" ctrllimited="true" ctrlrange="-80 80"/>
    <general name="0_actuator2" joint="0_joint2" ctrllimited="true" ctrlrange="-80 80"/>
    <general name="0_actuator3" joint="0_joint3" ctrllimited="true" ctrlrange="-80 80"/>
    <general name="0_actuator4" joint="0_joint4" ctrllimited="true" ctrlrange="-80 80"/>
    <general name="0_actuator5" joint="0_joint5" ctrllimited="true" ctrlrange="-80 80"/>
    <general name="0_actuator6" joint="0_joint6" ctrllimited="true" ctrlrange="-12 12"/>
    <general name="0_actuator7" joint="0_joint7" ctrllimited="true" ctrlrange="-12 12"/>
    <general name="0_actuator8" class="panda_hand" tendon="0_split" ctrlrange="0 255" forcerange="-100 100" gainprm="0.0156863" biasprm="0 -100 -10"/>
  </actuator>
</mujoco>
